<?xml version="1.0"?>
<robot name="kuka_minus">
  <link name="base_link">
    <inertial>
      <mass value="10.0"/>
      <origin xyz="0 0 0" rpy="0 0 0"/>
      <inertia ixx="0.1" ixy="0.0" ixz="0.0" iyy="0.1" iyz="0.0" izz="0.1"/>
    </inertial>
    <visual>
      <geometry>
        <box size="0.5 0.5 0.5"/>
      </geometry>
      <origin xyz="0 0 0" rpy="0 0 0"/>
    </visual>
    <collision>
      <geometry>
        <box size="0.5 0.5 0.5"/>
      </geometry>
      <origin xyz="0 0 0" rpy="0 0 0"/>
    </collision>
  </link>

  <joint name="joint_1" type="revolute">
    <parent link="base_link"/>
    <child link="link_1"/>
    <origin xyz="0 0 0.5" rpy="0 0 0"/>
    <axis xyz="0 0 1"/>
    <limit effort="10.0" lower="-1.57" upper="1.57" velocity="1.0"/>
  </joint>

  <link name="link_1">
    <inertial>
      <mass value="5.0"/>
      <origin xyz="0 0 0" rpy="0 0 0"/>
      <inertia ixx="0.05" ixy="0.0" ixz="0.0" iyy="0.05" iyz="0.0" izz="0.05"/>
    </inertial>
    <visual>
      <geometry>
        <cylinder radius="0.1" length="1.0"/>
      </geometry>
      <origin xyz="0 0 0.5" rpy="0 0 0"/>
    </visual>
    <collision>
      <geometry>
        <cylinder radius="0.1" length="1.0"/>
      </geometry>
      <origin xyz="0 0 0.5" rpy="0 0 0"/>
    </collision>
  </link>

  <joint name="joint_2" type="revolute">
    <parent link="link_1"/>
    <child link="link_2"/>
    <origin xyz="0 0 1.0" rpy="0 0 0"/>
    <axis xyz="0 0 1"/>
    <limit effort="10.0" lower="-1.57" upper="1.57" velocity="1.0"/>
  </joint>

  <link name="link_2">
    <inertial>
      <mass value="5.0"/>
      <origin xyz="0 0 0" rpy="0 0 0"/>
      <inertia ixx="0.05" ixy="0.0" ixz="0.0" iyy="0.05" iyz="0.0" izz="0.05"/>
    </inertial>
    <visual>
      <geometry>
        <cylinder radius="0.1" length="1.0"/>
      </geometry>
      <origin xyz="0 0 0.5" rpy="0 0 0"/>
    </visual>
    <collision>
      <geometry>
        <cylinder radius="0.1" length="1.0"/>
      </geometry>
      <origin xyz="0 0 0.5" rpy="0 0 0"/>
    </collision>
  </link>
</robot>